Workbook
Name Waveform_Overhead_for_Bourbon: [1]Constants!$B$1
Name Waveform_Overhead_for_Bourbon: [2]Constants!$B$1
Name x: [1]Constants!$B$1
Name x: [2]Constants!$B$1

Sheet Introduction
B2: EANAB | G2: Icewine | L2: Muscat | Q2: Whisky | V2: Cognac | AA2: Moonshine | AF2: Jaeger | AK2: Stinger | AP2: Malbec | AU2: Cava | AZ2: Barolo | BE2: Rossini | BI2: Sangria | BM2: Pisco | BQ2: Seabreeze
A3: Performance Bucket | B3: P0 | C3: P1 | D3: P2 | E3: P3 | F3: Others | G3: P0 | H3: P1 | I3: P2 | J3: P3 | K3: Others | L3: P0 | M3: P1 | N3: P2 | O3: P3 | P3: Others | Q3: P0 | R3: P1 | S3: P2 | T3: P3 | U3: Others | V3: P0 | W3: P1 | X3: P2 | Y3: P3 | Z3: Others | AA3: P0 | AB3: P1 | AC3: P2 | AD3: P3 | AE3: Others | AF3: P0 | AG3: P1 | AH3: P2 | AI3: P3 | AJ3: Others | AK3: P0 | AL3: P1 | AM3: P2 | AN3: P3 | AO3: Others | AP3: P0 | AQ3: P1 | AR3: P2 | AS3: P3 | AT3: Others | AU3: P0 | AV3: P1 | AW3: P2 | AX3: P3 | AY3: Others | AZ3: P0 | BA3: P1 | BB3: P2 | BC3: P3 | BD3: Others | BE3: P0 | BF3: P1 | BG3: P2 | BH3: P3 | BI3: P0 | BJ3: P1 | BK3: P2 | BL3: P3 | BM3: P0 | BN3: P1 | BO3: P2 | BP3: P3 | BQ3: P0 | BR3: P1 | BS3: P2 | BT3: P3 | BU3: comments
A4: 1. Better than baseline(GREEN) | B4: =COUNTIF('P0_All Devices'!DRL3:DRL36,"1. Better than baseline ") -> 0 | C4: =COUNTIF('P1(Stopwatch)'!ACE3:ACE7,"1. Better than baseline ")+COUNTIF(P1_P2_P3_Automation!CAJ3:CAJ15,"1. Better than baseline") -> 10 | D4: =COUNTIF('P2(Stopwatch)'!AAN3:AAN18,"1. Better than baseline ")+COUNTIF(P1_P2_P3_Automation!CAJ18:CAJ31,"1. Better than baseline") -> 29 | E4: =COUNTIF('P3(Stopwatch)'!ABK3:ABK12,"1. Better than baseline ")+COUNTIF(P1_P2_P3_Automation!CAJ32:CAJ32,"1. Better than baseline") -> 9 | F4: =COUNTIF('One time execution_Milestone'!BT4:BT64,"1. Better than baseline ") -> 24 | G4: =COUNTIF('P0_All Devices'!DRM3:DRM36,"1. Better than baseline ") -> 2 | H4: =COUNTIF('P1(Stopwatch)'!ACF3:ACF7,"1. Better than baseline ")+COUNTIF(P1_P2_P3_Automation!CAK3:CAK11,"1. Better than baseline ") -> 6 | I4: =COUNTIF('P2(Stopwatch)'!AAO3:AAO14,"1. Better than baseline ")+COUNTIF(P1_P2_P3_Automation!CAK18:CAK31,"1. Better than baseline ") -> 14 | J4: =COUNTIF('P3(Stopwatch)'!ABL3:ABL3,"1. Better than baseline ")+COUNTIF(P1_P2_P3_Automation!CAK32:CAK32,"1. Better than baseline ") -> 1 | K4: =COUNTIF('One time execution_Milestone'!BU4:BU64,"1. Better than baseline ") -> 49 | L4: =COUNTIF('P0_All Devices'!DRN3:DRN36,"1. Better than baseline ") -> 0 | M4: =COUNTIF('P1(Stopwatch)'!ACG3:ACG7,"1. Better than baseline ")+COUNTIF(P1_P2_P3_Automation!CAL3:CAL15,"1. Better than baseline ") -> 7 | N4: =COUNTIF('P2(Stopwatch)'!AAP3:AAP18,"1. Better than baseline ")+COUNTIF(P1_P2_P3_Automation!CAL18:CAL31,"1. Better than baseline ") -> 15 | O4: =COUNTIF('P3(Stopwatch)'!ABM3:ABM12,"1. Better than baseline ")+COUNTIF(P1_P2_P3_Automation!CAL32:CAL32,"1. Better than baseline ") -> 1 | P4: =COUNTIF('One time execution_Milestone'!BV4:BV64,"1. Better than baseline ") -> 49 | Q4: =COUNTIF('P0_All Devices'!DRO3:DRO36,"1. Better than baseline ") -> 0 | R4: =COUNTIF('P1(Stopwatch)'!ACH3:ACH7,"1. Better than baseline ")+COUNTIF(P1_P2_P3_Automation!CAM3:CAM15,"1. Better than baseline ") -> 8 | S4: =COUNTIF('P2(Stopwatch)'!AAQ3:AAQ18,"1. Better than baseline ")+COUNTIF(P1_P2_P3_Automation!CAM18:CAM31,"1. Better than baseline ") -> 13 | T4: =COUNTIF('P3(Stopwatch)'!ABN3:ABN12,"1. Better than baseline ")+COUNTIF(P1_P2_P3_Automation!CAM32:CAM32,"1. Better than baseline ") -> 0 | U4: =COUNTIF('One time execution_Milestone'!BW4:BW64,"1. Better than baseline ") -> 55 | V4: =COUNTIF('P0_All Devices'!DRP3:DRP36,"1. Better than baseline ") -> 34 | W4: =COUNTIF('P1(Stopwatch)'!ACI3:ACI7,"1. Better than baseline ")+COUNTIF(P1_P2_P3_Automation!CAN3:CAN15,"1. Better than baseline ") -> 15 | X4: =COUNTIF('P2(Stopwatch)'!AAR3:AAR18,"1. Better than baseline ")+COUNTIF(P1_P2_P3_Automation!CAN18:CAN31,"1. Better than baseline ") -> 29 | Y4: =COUNTIF('P3(Stopwatch)'!ABO3:ABO12,"1. Better than baseline ")+COUNTIF(P1_P2_P3_Automation!CAN32:CAN32,"1. Better than baseline ") -> 11 | Z4: =COUNTIF('One time execution_Milestone'!BX4:BX64,"1. Better than baseline ") -> 61 | AA4: =COUNTIF('P0_All Devices'!DRQ3:DRQ36,"1. Better than baseline ") -> 3 | AB4: =COUNTIF('P1(Stopwatch)'!ACJ3:ACJ7,"1. Better than baseline ")+COUNTIF(P1_P2_P3_Automation!CAO3:CAO15,"1. Better than baseline ") -> 2 | AC4: =COUNTIF('P2(Stopwatch)'!AAS3:AAS18,"1. Better than baseline ")+COUNTIF(P1_P2_P3_Automation!CAO18:CAO31,"1. Better than baseline ") -> 13 | AD4: =COUNTIF('P3(Stopwatch)'!ABP3:ABP12,"1. Better than baseline ")+COUNTIF(P1_P2_P3_Automation!CAO32:CAO32,"1. Better than baseline ") -> 10 | AE4: =COUNTIF('One time execution_Milestone'!BY4:BY64,"1. Better than baseline ") -> 55 | AF4: =COUNTIF('P0_All Devices'!DRR3:DRR36,"1. Better than baseline ") -> 3 | AG4: =COUNTIF('P1(Stopwatch)'!ACK3:ACK7,"1. Better than baseline ")+COUNTIF(P1_P2_P3_Automation!CAP3:CAP15,"1. Better than baseline ") -> 2 | AH4: =COUNTIF('P2(Stopwatch)'!AAT3:AAT18,"1. Better than baseline ")+COUNTIF(P1_P2_P3_Automation!CAP18:CAP31,"1. Better than baseline ") -> 20 | AI4: =COUNTIF('P3(Stopwatch)'!ABQ3:ABQ12,"1. Better than baseline ")+COUNTIF(P1_P2_P3_Automation!CAP32:CAP32,"1. Better than baseline ") -> 10 | AJ4: =COUNTIF('One time execution_Milestone'!BZ4:BZ64,"1. Better than baseline ") -> 25 | AK4: =COUNTIF('P0_All Devices'!DRS3:DRS36,"1. Better than baseline ") -> 1 | AL4: =COUNTIF('P1(Stopwatch)'!ACL3:ACL7,"1. Better than baseline ")+COUNTIF(P1_P2_P3_Automation!CAQ3:CAQ15,"1. Better than baseline ") -> 7 | AM4: =COUNTIF('P2(Stopwatch)'!AAU3:AAU18,"1. Better than baseline ")+COUNTIF(P1_P2_P3_Automation!CAQ18:CAQ31,"1. Better than baseline ") -> 3 | AN4: =COUNTIF('P3(Stopwatch)'!ABR3:ABR12,"1. Better than baseline ")+COUNTIF(P1_P2_P3_Automation!CAQ32:CAQ32,"1. Better than baseline ") -> 11 | AO4: =COUNTIF('One time execution_Milestone'!CA4:CA64,"1. Better than baseline ") -> 61 | AP4: =COUNTIF('P0_All Devices'!DRT3:DRT36,"1. Better than baseline ") -> 32 | AQ4: =COUNTIF('P1(Stopwatch)'!ACN3:ACN7,"1. Better than baseline ")+COUNTIF(P1_P2_P3_Automation!CAR3:CAR15,"1. Better than baseline ") -> 2 | AR4: =COUNTIF('P2(Stopwatch)'!AAV3:AAV18,"1. Better than baseline ")+COUNTIF(P1_P2_P3_Automation!CAR18:CAR31,"1. Better than baseline ") -> 3 | AS4: =COUNTIF('P3(Stopwatch)'!ABS3:ABS12,"1. Better than baseline ")+COUNTIF(P1_P2_P3_Automation!CAR32:CAR32,"1. Better than baseline ") -> 0 | AT4: =COUNTIF('One time execution_Milestone'!CF4:CF64,"1. Better than baseline ") -> 0 | AU4: =COUNTIF('P0_All Devices'!DRU3:DRU36,"1. Better than baseline ") -> 33 | AV4: =COUNTIF('P1(Stopwatch)'!ACO3:ACO8,"1. Better than baseline ")+COUNTIF(P1_P2_P3_Automation!CAW3:CAW15,"1. Better than baseline ") -> 13 | AW4: =COUNTIF('P2(Stopwatch)'!AAW3:AAW18,"1. Better than baseline ")+COUNTIF(P1_P2_P3_Automation!CAS18:CAS31,"1. Better than baseline ") -> 3 | AX4: =COUNTIF('P3(Stopwatch)'!ABT3:ABT12,"1. Better than baseline ")+COUNTIF(P1_P2_P3_Automation!CAS32:CAS32,"1. Better than baseline ") -> 0 | AY4: =COUNTIF('One time execution_Milestone'!CK4:CK64,"1. Better than baseline ") -> 0 | AZ4: =COUNTIF('P0_All Devices'!DRV3:DRV36,"1. Better than baseline ") -> 32 | BA4: =COUNTIF('P1(Stopwatch)'!ACP3:ACP7,"1. Better than baseline ")+COUNTIF(P1_P2_P3_Automation!CAT3:CAT17,"1. Better than baseline ") -> 17 | BB4: =COUNTIF('P2(Stopwatch)'!AAX3:AAX18,"1. Better than baseline ")+COUNTIF(P1_P2_P3_Automation!CAT18:CAT31,"1. Better than baseline ") -> 14 | BC4: =COUNTIF('P3(Stopwatch)'!ABU3:ABU12,"1. Better than baseline ")+COUNTIF(P1_P2_P3_Automation!CAT32:CAT32,"1. Better than baseline ") -> 11 | BD4: =COUNTIF('One time execution_Milestone'!CP4:CP64,"1. Better than baseline ") -> 0 | BE4: =COUNTIF([3]P0!CVW3:CVW36,"1. Better than baseline ") -> #VALUE! | BF4: =COUNTIF('[3]P1(Stopwatch)'!UH3:UH41,"1. Better than baseline ")+COUNTIF([3]P1_P2_P3_Automation!CAO3:CAR17,"1. Better than baseline ") -> #VALUE! | BG4: =COUNTIF('[3]P2(Stopwatch)'!SX3:SX30,"1. Better than baseline ")+COUNTIF([3]P1_P2_P3_Automation!CAO18:CAO31,"1. Better than baseline ") -> #VALUE! | BH4: =COUNTIF('[3]P3(Stopwatch)'!VO3:VO23,"1. Better than baseline ")+COUNTIF([3]P1_P2_P3_Automation!CAO32:CAO32,"1. Better than baseline ") -> #VALUE! | BI4: =COUNTIF([3]P0!CVX3:CVX36,"1. Better than baseline ") -> #VALUE! | BJ4: =COUNTIF('[3]P1(Stopwatch)'!UL3:UL41,"1. Better than baseline ")+COUNTIF([3]P1_P2_P3_Automation!CAS3:CAV17,"1. Better than baseline ") -> #VALUE! | BK4: =COUNTIF('[3]P2(Stopwatch)'!TB3:TB30,"1. Better than baseline ")+COUNTIF([3]P1_P2_P3_Automation!CAS18:CAS31,"1. Better than baseline ") -> #VALUE! | BL4: =COUNTIF('[3]P3(Stopwatch)'!VS3:VS23,"1. Better than baseline ")+COUNTIF([3]P1_P2_P3_Automation!CAS32:CAS32,"1. Better than baseline ") -> #VALUE! | BM4: =COUNTIF([3]P0!CVY3:CVY36,"1. Better than baseline ")+COUNTIF('[3]P0 Pisco & Barolo'!CP5:CP24,"1. Better than baseline ")+COUNTIF('[3]Canvas and Structured '!BV4:BV11,"1. Better than baseline ") -> #VALUE! | BN4: =COUNTIF('[3]P1(Stopwatch)'!UP3:UP41,"1. Better than baseline ")+COUNTIF([3]P1_P2_P3_Automation!CAW3:CAZ17,"1. Better than baseline ") -> #VALUE! | BO4: =COUNTIF('[3]P2(Stopwatch)'!TF3:TF30,"1. Better than baseline ")+COUNTIF([3]P1_P2_P3_Automation!CAW18:CAW31,"1. Better than baseline ") -> #VALUE! | BP4: =COUNTIF('[3]P3(Stopwatch)'!VW3:VW23,"1. Better than baseline ")+COUNTIF([3]P1_P2_P3_Automation!CAW32:CAW32,"1. Better than baseline ") -> #VALUE! | BQ4: =COUNTIF([3]P0_Seabreeze!BU3:BU65,"1. Better than baseline ") -> #VALUE! | BR4: =COUNTIF('[3]P1(Stopwatch)'!UT3:UT41,"1. Better than baseline ")+COUNTIF([3]P1_P2_P3_Automation!CBA3:CBD17,"1. Better than baseline ") -> #VALUE! | BS4: =COUNTIF('[3]P2(Stopwatch)'!TJ3:TJ30,"1. Better than baseline ")+COUNTIF([3]P1_P2_P3_Automation!CBA18:CBA31,"1. Better than baseline ") -> #VALUE! | BT4: =COUNTIF('[3]P3(Stopwatch)'!WA3:WA23,"1. Better than baseline ")+COUNTIF([3]P1_P2_P3_Automation!CBA32:CBA32,"1. Better than baseline ") -> #VALUE!
A5: 2. Within 10% deviation from baseline(YELLOW) | B5: =COUNTIF('P0_All Devices'!DRL3:DRL36,"2. Within 10% deviation from baseline") -> 16 | C5: =COUNTIF('P1(Stopwatch)'!ACE3:ACE7,"2. Within 10% deviation from baseline")+COUNTIF(P1_P2_P3_Automation!CAJ3:CAJ15,"2. Within 10% deviation from baseline") -> 5 | D5: =COUNTIF('P2(Stopwatch)'!AAN3:AAN18,"2. Within 10% deviation from baseline")+COUNTIF(P1_P2_P3_Automation!CAJ18:CAJ31,"2. Within 10% deviation from baseline") -> 0 | E5: =COUNTIF('P3(Stopwatch)'!ABK3:ABK12,"2. Within 10% deviation from baseline")+COUNTIF(P1_P2_P3_Automation!CAJ32:CAJ32,"2. Within 10% deviation from baseline") -> 1 | F5: =COUNTIF('One time execution_Milestone'!BT4:BT64,"2. Within 10% deviation from baseline") -> 31 | G5: =COUNTIF('P0_All Devices'!DRM3:DRM36,"2. Within 10% deviation from baseline") -> 27 | H5: =COUNTIF('P1(Stopwatch)'!ACF3:ACF7,"2. Within 10% deviation from baseline")+COUNTIF(P1_P2_P3_Automation!CAK3:CAK11,"2. Within 10% deviation from baseline") -> 8 | I5: =COUNTIF('P2(Stopwatch)'!AAO3:AAO14,"2. Within 10% deviation from baseline")+COUNTIF(P1_P2_P3_Automation!CAK18:CAK31,"2. Within 10% deviation from baseline") -> 3 | J5: =COUNTIF('P3(Stopwatch)'!ABL3:ABL3,"2. Within 10% deviation from baseline")+COUNTIF(P1_P2_P3_Automation!CAK32:CAK32,"2. Within 10% deviation from baseline") -> 1 | K5: =COUNTIF('One time execution_Milestone'!BU4:BU64,"2. Within 10% deviation from baseline") -> 0 | L5: =COUNTIF('P0_All Devices'!DRN3:DRN36,"2. Within 10% deviation from baseline") -> 17 | M5: =COUNTIF('P1(Stopwatch)'!ACG3:ACG7,"2. Within 10% deviation from baseline")+COUNTIF(P1_P2_P3_Automation!CAL3:CAL15,"2. Within 10% deviation from baseline") -> 6 | N5: =COUNTIF('P2(Stopwatch)'!AAP3:AAP18,"2. Within 10% deviation from baseline")+COUNTIF(P1_P2_P3_Automation!CAL18:CAL31,"2. Within 10% deviation from baseline") -> 5 | O5: =COUNTIF('P3(Stopwatch)'!ABM3:ABM12,"2. Within 10% deviation from baseline")+COUNTIF(P1_P2_P3_Automation!CAL32:CAL32,"2. Within 10% deviation from baseline") -> 5 | P5: =COUNTIF('One time execution_Milestone'!BV4:BV64,"2. Within 10% deviation from baseline") -> 0 | Q5: =COUNTIF('P0_All Devices'!DRO3:DRO36,"2. Within 10% deviation from baseline") -> 17 | R5: =COUNTIF('P1(Stopwatch)'!ACH3:ACH7,"2. Within 10% deviation from baseline")+COUNTIF(P1_P2_P3_Automation!CAM3:CAM15,"2. Within 10% deviation from baseline") -> 5 | S5: =COUNTIF('P2(Stopwatch)'!AAQ3:AAQ18,"2. Within 10% deviation from baseline")+COUNTIF(P1_P2_P3_Automation!CAM18:CAM31,"2. Within 10% deviation from baseline") -> 15 | T5: =COUNTIF('P3(Stopwatch)'!ABN3:ABN12,"2. Within 10% deviation from baseline")+COUNTIF(P1_P2_P3_Automation!CAM32:CAM32,"2. Within 10% deviation from baseline") -> 10 | U5: =COUNTIF('One time execution_Milestone'!BW4:BW64,"2. Within 10% deviation from baseline") -> 0 | V5: =COUNTIF('P0_All Devices'!DRP3:DRP36,"2. Within 10% deviation from baseline") -> 0 | W5: =COUNTIF('P1(Stopwatch)'!ACI3:ACI7,"2. Within 10% deviation from baseline")+COUNTIF(P1_P2_P3_Automation!CAN3:CAN15,"2. Within 10% deviation from baseline") -> 0 | X5: =COUNTIF('P2(Stopwatch)'!AAR3:AAR18,"2. Within 10% deviation from baseline")+COUNTIF(P1_P2_P3_Automation!CAN18:CAN31,"2. Within 10% deviation from baseline") -> 0 | Y5: =COUNTIF('P3(Stopwatch)'!ABO3:ABO12,"2. Within 10% deviation from baseline")+COUNTIF(P1_P2_P3_Automation!CAN32:CAN32,"2. Within 10% deviation from baseline") -> 0 | Z5: =COUNTIF('One time execution_Milestone'!BX4:BX64,"2. Within 10% deviation from baseline") -> 0 | AA5: =COUNTIF('P0_All Devices'!DRQ3:DRQ36,"2. Within 10% deviation from baseline") -> 18 | AB5: =COUNTIF('P1(Stopwatch)'!ACJ3:ACJ7,"2. Within 10% deviation from baseline")+COUNTIF(P1_P2_P3_Automation!CAO3:CAO15,"2. Within 10% deviation from baseline") -> 8 | AC5: =COUNTIF('P2(Stopwatch)'!AAS3:AAS18,"2. Within 10% deviation from baseline")+COUNTIF(P1_P2_P3_Automation!CAO18:CAO31,"2. Within 10% deviation from baseline") -> 2 | AD5: =COUNTIF('P3(Stopwatch)'!ABP3:ABP12,"2. Within 10% deviation from baseline")+COUNTIF(P1_P2_P3_Automation!CAO32:CAO32,"2. Within 10% deviation from baseline") -> 0 | AE5: =COUNTIF('One time execution_Milestone'!BY4:BY64,"2. Within 10% deviation from baseline") -> 0 | AF5: =COUNTIF('P0_All Devices'!DRR3:DRR36,"2. Within 10% deviation from baseline") -> 17 | AG5: =COUNTIF('P1(Stopwatch)'!ACK3:ACK7,"2. Within 10% deviation from baseline")+COUNTIF(P1_P2_P3_Automation!CAP3:CAP15,"2. Within 10% deviation from baseline") -> 7 | AH5: =COUNTIF('P2(Stopwatch)'!AAT3:AAT18,"2. Within 10% deviation from baseline")+COUNTIF(P1_P2_P3_Automation!CAP18:CAP31,"2. Within 10% deviation from baseline") -> 4 | AI5: =COUNTIF('P3(Stopwatch)'!ABQ3:ABQ12,"2. Within 10% deviation from baseline")+COUNTIF(P1_P2_P3_Automation!CAP32:CAP32,"2. Within 10% deviation from baseline") -> 0 | AJ5: =COUNTIF('One time execution_Milestone'!BZ4:BZ64,"2. Within 10% deviation from baseline") -> 30 | AK5: =COUNTIF('P0_All Devices'!DRS3:DRS36,"2. Within 10% deviation from baseline") -> 14 | AL5: =COUNTIF('P1(Stopwatch)'!ACL3:ACL7,"2. Within 10% deviation from baseline")+COUNTIF(P1_P2_P3_Automation!CAQ3:CAQ15,"2. Within 10% deviation from baseline") -> 4 | AM5: =COUNTIF('P2(Stopwatch)'!AAU3:AAU18,"2. Within 10% deviation from baseline")+COUNTIF(P1_P2_P3_Automation!CAQ18:CAQ31,"2. Within 10% deviation from baseline") -> 17 | AN5: =COUNTIF('P3(Stopwatch)'!ABR3:ABR12,"2. Within 10% deviation from baseline")+COUNTIF(P1_P2_P3_Automation!CAQ32:CAQ32,"2. Within 10% deviation from baseline") -> 0 | AO5: =COUNTIF('One time execution_Milestone'!CA4:CA64,"2. Within 10% deviation from baseline") -> 0 | AP5: =COUNTIF('P0_All Devices'!DRT3:DRT36,"2. Within 10% deviation from baseline") -> 2 | AQ5: =COUNTIF('P1(Stopwatch)'!ACN3:ACN7,"2. Within 10% deviation from baseline")+COUNTIF(P1_P2_P3_Automation!CAR3:CAR15,"2. Within 10% deviation from baseline") -> 4 | AR5: =COUNTIF('P2(Stopwatch)'!AAV3:AAV18,"2. Within 10% deviation from baseline")+COUNTIF(P1_P2_P3_Automation!CAR18:CAR31,"2. Within 10% deviation from baseline") -> 13 | AS5: =COUNTIF('P3(Stopwatch)'!ABS3:ABS12,"2. Within 10% deviation from baseline")+COUNTIF(P1_P2_P3_Automation!CAR32:CAR32,"2. Within 10% deviation from baseline") -> 7 | AT5: =COUNTIF('One time execution_Milestone'!CF4:CF64,"2. Within 10% deviation from baseline") -> 0 | AU5: =COUNTIF('P0_All Devices'!DRU3:DRU36,"2. Within 10% deviation from baseline") -> 1 | AV5: =COUNTIF('P1(Stopwatch)'!ACO3:ACO8,"2. Within 10% deviation from baseline")+COUNTIF(P1_P2_P3_Automation!CAW3:CAW15,"2. Within 10% deviation from baseline") -> 3 | AW5: =COUNTIF('P2(Stopwatch)'!AAW3:AAW18,"2. Within 10% deviation from baseline")+COUNTIF(P1_P2_P3_Automation!CAS18:CAS31,"2. Within 10% deviation from baseline") -> 12 | AX5: =COUNTIF('P3(Stopwatch)'!ABT3:ABT12,"2. Within 10% deviation from baseline")+COUNTIF(P1_P2_P3_Automation!CAS32:CAS32,"2. Within 10% deviation from baseline") -> 8 | AY5: =COUNTIF('One time execution_Milestone'!CK4:CK64,"2. Within 10% deviation from baseline") -> 0 | AZ5: =COUNTIF('P0_All Devices'!DRV3:DRV36,"2. Within 10% deviation from baseline") -> 2 | BA5: =COUNTIF('P1(Stopwatch)'!ACP3:ACP7,"2. Within 10% deviation from baseline")+COUNTIF(P1_P2_P3_Automation!CAT3:CAT17,"2. Within 10% deviation from baseline") -> 1 | BB5: =COUNTIF('P2(Stopwatch)'!AAX3:AAX18,"2. Within 10% deviation from baseline")+COUNTIF(P1_P2_P3_Automation!CAT18:CAT31,"2. Within 10% deviation from baseline") -> 8 | BC5: =COUNTIF('P3(Stopwatch)'!ABU3:ABU12,"2. Within 10% deviation from baseline")+COUNTIF(P1_P2_P3_Automation!CAT32:CAT32,"2. Within 10% deviation from baseline") -> 0 | BD5: =COUNTIF('One time execution_Milestone'!CP4:CP64,"2. Within 10% deviation from baseline") -> 0 | BE5: =COUNTIF([3]P0!CVW3:CVW36,"2. Within 10% deviation from baseline") -> #VALUE! | BF5: =COUNTIF('[3]P1(Stopwatch)'!UH3:UH41,"2. Within 10% deviation from baseline")+COUNTIF([3]P1_P2_P3_Automation!CAO3:CAO17,"2. Within 10% deviation from baseline") -> #VALUE! | BG5: =COUNTIF('[3]P2(Stopwatch)'!SX3:SX30,"2. Within 10% deviation from baseline")+COUNTIF([3]P1_P2_P3_Automation!CAO18:CAO31,"2. Within 10% deviation from baseline") -> #VALUE! | BH5: =COUNTIF('[3]P3(Stopwatch)'!VO3:VO23,"2. Within 10% deviation from baseline")+COUNTIF([3]P1_P2_P3_Automation!CAO32:CAO32,"2. Within 10% deviation from baseline") -> #VALUE! | BI5: =COUNTIF([3]P0!CVX3:CVX36,"2. Within 10% deviation from baseline") -> #VALUE! | BJ5: =COUNTIF('[3]P1(Stopwatch)'!UL3:UL41,"2. Within 10% deviation from baseline")+COUNTIF([3]P1_P2_P3_Automation!CAS3:CAS17,"2. Within 10% deviation from baseline") -> #VALUE! | BK5: =COUNTIF('[3]P2(Stopwatch)'!TB3:TB30,"2. Within 10% deviation from baseline")+COUNTIF([3]P1_P2_P3_Automation!CAS18:CAS31,"2. Within 10% deviation from baseline") -> #VALUE! | BL5: =COUNTIF('[3]P3(Stopwatch)'!VS3:VS23,"2. Within 10% deviation from baseline")+COUNTIF([3]P1_P2_P3_Automation!CAS32:CAS32,"2. Within 10% deviation from baseline") -> #VALUE! | BM5: =COUNTIF([3]P0!CVY3:CVY36,"2. Within 10% deviation from baseline")+COUNTIF('[3]P0 Pisco & Barolo'!CP5:CP24,"2. Within 10% deviation from baseline")+COUNTIF('[3]Canvas and Structured '!BV4:BV11,"2. Within 10% deviation from baseline") -> #VALUE! | BN5: =COUNTIF('[3]P1(Stopwatch)'!UP3:UP41,"2. Within 10% deviation from baseline")+COUNTIF([3]P1_P2_P3_Automation!CAW3:CAW17,"2. Within 10% deviation from baseline") -> #VALUE! | BO5: =COUNTIF('[3]P2(Stopwatch)'!TF3:TF30,"2. Within 10% deviation from baseline")+COUNTIF([3]P1_P2_P3_Automation!CAW18:CAW31,"2. Within 10% deviation from baseline") -> #VALUE! | BP5: =COUNTIF('[3]P3(Stopwatch)'!VW3:VW23,"2. Within 10% deviation from baseline")+COUNTIF([3]P1_P2_P3_Automation!CAW32:CAW32,"2. Within 10% deviation from baseline") -> #VALUE! | BQ5: =COUNTIF([3]P0_Seabreeze!BU3:BU65,"2. Within 10% deviation from baseline") -> #VALUE! | BR5: =COUNTIF('[3]P1(Stopwatch)'!UT3:UT41,"2. Within 10% deviation from baseline")+COUNTIF([3]P1_P2_P3_Automation!CBA3:CBA17,"2. Within 10% deviation from baseline") -> #VALUE! | BS5: =COUNTIF('[3]P2(Stopwatch)'!TJ3:TJ30,"2. Within 10% deviation from baseline")+COUNTIF([3]P1_P2_P3_Automation!CBA18:CBA31,"2. Within 10% deviation from baseline") -> #VALUE! | BT5: =COUNTIF('[3]P3(Stopwatch)'!WA3:WA23,"2. Within 10% deviation from baseline")+COUNTIF([3]P1_P2_P3_Automation!CBA32:CBA32,"2. Within 10% deviation from baseline") -> #VALUE!
A6: 3. >10% from baseline(RED) | B6: =COUNTIF('P0_All Devices'!DRL3:DRL36,"3. Missing baseline") -> 18 | C6: =COUNTIF('P1(Stopwatch)'!ACE3:ACE7,"3. Missing baseline")+COUNTIF(P1_P2_P3_Automation!CAJ3:CAJ117,"3. Missing baseline") -> 0 | D6: =COUNTIF('P2(Stopwatch)'!AAN3:AAN18,"3. Missing baseline")+COUNTIF(P1_P2_P3_Automation!CAJ18:CAJ31,"3. Missing baseline") -> 0 | E6: =COUNTIF('P3(Stopwatch)'!ABK3:ABK12,"3. Missing baseline")+COUNTIF(P1_P2_P3_Automation!CAJ32:CAJ32,"3. Missing baseline") -> 0 | F6: =COUNTIF('One time execution_Milestone'!BT4:BT64,"3. Missing baseline") -> 0 | G6: =COUNTIF('P0_All Devices'!DRM3:DRM36,"3. Missing baseline") -> 5 | H6: =COUNTIF('P1(Stopwatch)'!ACF3:ACF7,"3. Missing baseline")+COUNTIF(P1_P2_P3_Automation!CAK3:CAK11,"3. Missing baseline") -> 0 | I6: =COUNTIF('P2(Stopwatch)'!AAO3:AAO14,"3. Missing baseline")+COUNTIF(P1_P2_P3_Automation!CAK18:CAK31,"3. Missing baseline") -> 0 | J6: =COUNTIF('P3(Stopwatch)'!ABL3:ABL3,"3. Missing baseline")+COUNTIF(P1_P2_P3_Automation!CAK32:CAK32,"3. Missing baseline") -> 0 | K6: =COUNTIF('One time execution_Milestone'!BU4:BU64,"3. Missing baseline") -> 0 | L6: =COUNTIF('P0_All Devices'!DRN3:DRN36,"3. Missing baseline") -> 17 | M6: =COUNTIF('P1(Stopwatch)'!ACG3:ACG7,"3. Missing baseline")+COUNTIF(P1_P2_P3_Automation!CAL3:CAL15,"3. Missing baseline") -> 2 | N6: =COUNTIF('P2(Stopwatch)'!AAP3:AAP18,"3. Missing baseline")+COUNTIF(P1_P2_P3_Automation!CAL18:CAL31,"3. Missing baseline") -> 2 | O6: =COUNTIF('P3(Stopwatch)'!ABM3:ABM12,"3. Missing baseline")+COUNTIF(P1_P2_P3_Automation!CAL32:CAL32,"3. Missing baseline") -> 0 | P6: =COUNTIF('One time execution_Milestone'!BV4:BV64,"3. Missing baseline") -> 0 | Q6: =COUNTIF('P0_All Devices'!DRO3:DRO36,"3. Missing baseline") -> 17 | R6: =COUNTIF('P1(Stopwatch)'!ACH3:ACH7,"3. Missing baseline")+COUNTIF(P1_P2_P3_Automation!CAM3:CAM15,"3. Missing baseline") -> 2 | S6: =COUNTIF('P2(Stopwatch)'!AAQ3:AAQ18,"3. Missing baseline")+COUNTIF(P1_P2_P3_Automation!CAM18:CAM31,"3. Missing baseline") -> 1 | T6: =COUNTIF('P3(Stopwatch)'!ABN3:ABN12,"3. Missing baseline")+COUNTIF(P1_P2_P3_Automation!CAM32:CAM32,"3. Missing baseline") -> 0 | U6: =COUNTIF('One time execution_Milestone'!BW4:BW64,"3. Missing baseline") -> 0 | V6: =COUNTIF('P0_All Devices'!DRP3:DRP36,"3. Missing baseline") -> 0 | W6: =COUNTIF('P1(Stopwatch)'!ACI3:ACI7,"3. Missing baseline")+COUNTIF(P1_P2_P3_Automation!CAN3:CAN15,"3. Missing baseline") -> 0 | X6: =COUNTIF('P2(Stopwatch)'!AAR3:AAR18,"3. Missing baseline")+COUNTIF(P1_P2_P3_Automation!CAN18:CAN31,"3. Missing baseline") -> 0 | Y6: =COUNTIF('P3(Stopwatch)'!ABO3:ABO12,"3. Missing baseline")+COUNTIF(P1_P2_P3_Automation!CAN32:CAN32,"3. Missing baseline") -> 0 | Z6: =COUNTIF('One time execution_Milestone'!BX4:BX64,"3. Missing baseline") -> 0 | AA6: =COUNTIF('P0_All Devices'!DRQ3:DRQ36,"3. Missing baseline") -> 13 | AB6: =COUNTIF('P1(Stopwatch)'!ACJ3:ACJ7,"3. Missing baseline")+COUNTIF(P1_P2_P3_Automation!CAO3:CAO15,"3. Missing baseline") -> 5 | AC6: =COUNTIF('P2(Stopwatch)'!AAS3:AAS18,"3. Missing baseline")+COUNTIF(P1_P2_P3_Automation!CAO18:CAO31,"3. Missing baseline") -> 11 | AD6: =COUNTIF('P3(Stopwatch)'!ABP3:ABP12,"3. Missing baseline")+COUNTIF(P1_P2_P3_Automation!CAO32:CAO32,"3. Missing baseline") -> 0 | AE6: =COUNTIF('One time execution_Milestone'!BY4:BY64,"3. Missing baseline") -> 0 | AF6: =COUNTIF('P0_All Devices'!DRR3:DRR36,"3. Missing baseline") -> 14 | AG6: =COUNTIF('P1(Stopwatch)'!ACK3:ACK7,"3. Missing baseline")+COUNTIF(P1_P2_P3_Automation!CAP3:CAP117,"3. Missing baseline") -> 14 | AH6: =COUNTIF('P2(Stopwatch)'!AAT3:AAT18,"3. Missing baseline")+COUNTIF(P1_P2_P3_Automation!CAP18:CAP31,"3. Missing baseline") -> 6 | AI6: =COUNTIF('P3(Stopwatch)'!ABQ3:ABQ12,"3. Missing baseline")+COUNTIF(P1_P2_P3_Automation!CAP32:CAP32,"3. Missing baseline") -> 0 | AJ6: =COUNTIF('One time execution_Milestone'!BZ4:BZ64,"3. Missing baseline") -> 0 | AK6: =COUNTIF('P0_All Devices'!DRS3:DRS36,"3. Missing baseline") -> 19 | AL6: =COUNTIF('P1(Stopwatch)'!ACL3:ACL7,"3. Missing baseline")+COUNTIF(P1_P2_P3_Automation!CAQ3:CAQ15,"3. Missing baseline") -> 7 | AM6: =COUNTIF('P2(Stopwatch)'!AAU3:AAU18,"3. Missing baseline")+COUNTIF(P1_P2_P3_Automation!CAQ18:CAQ31,"3. Missing baseline") -> 7 | AN6: =COUNTIF('P3(Stopwatch)'!ABR3:ABR12,"3. Missing baseline")+COUNTIF(P1_P2_P3_Automation!CAQ32:CAQ32,"3. Missing baseline") -> 0 | AO6: =COUNTIF('One time execution_Milestone'!CA4:CA64,"3. Missing baseline") -> 0 | AP6: =COUNTIF('P0_All Devices'!DRT3:DRT36,"3. Missing baseline") -> 0 | AQ6: =COUNTIF('P1(Stopwatch)'!ACN3:ACN7,"3. Missing baseline")+COUNTIF(P1_P2_P3_Automation!CAR3:CAR15,"3. Missing baseline") -> 9 | AR6: =COUNTIF('P2(Stopwatch)'!AAV3:AAV18,"3. Missing baseline")+COUNTIF(P1_P2_P3_Automation!CAR18:CAR31,"3. Missing baseline") -> 10 | AS6: =COUNTIF('P3(Stopwatch)'!ABS3:ABS12,"3. Missing baseline")+COUNTIF(P1_P2_P3_Automation!CAR32:CAR32,"3. Missing baseline") -> 3 | AT6: =COUNTIF('One time execution_Milestone'!CF4:CF64,"3. Missing baseline") -> 0 | AU6: =COUNTIF('P0_All Devices'!DRU3:DRU36,"3. Missing baseline") -> 0 | AV6: =COUNTIF('P1(Stopwatch)'!ACO3:ACO8,"3. Missing baseline")+COUNTIF(P1_P2_P3_Automation!CAW3:CAW15,"3. Missing baseline") -> 2 | AW6: =COUNTIF('P2(Stopwatch)'!AAW3:AAW18,"3. Missing baseline")+COUNTIF(P1_P2_P3_Automation!CAS18:CAS31,"3. Missing baseline") -> 11 | AX6: =COUNTIF('P3(Stopwatch)'!ABT3:ABT12,"3. Missing baseline")+COUNTIF(P1_P2_P3_Automation!CAS32:CAS32,"3. Missing baseline") -> 2 | AY6: =COUNTIF('One time execution_Milestone'!CK4:CK64,"3. Missing baseline") -> 0 | AZ6: =COUNTIF('P0_All Devices'!DRV3:DRV36,"3. Missing baseline") -> 0 | BA6: =COUNTIF('P1(Stopwatch)'!ACP3:ACP7,"3. Missing baseline")+COUNTIF(P1_P2_P3_Automation!CAT3:CAT17,"3. Missing baseline") -> 0 | BB6: =COUNTIF('P2(Stopwatch)'!AAX3:AAX18,"3. Missing baseline")+COUNTIF(P1_P2_P3_Automation!CAT18:CAT31,"3. Missing baseline") -> 0 | BC6: =COUNTIF('P3(Stopwatch)'!ABU3:ABU12,"3. Missing baseline")+COUNTIF(P1_P2_P3_Automation!CAT32:CAT32,"3. Missing baseline") -> 0 | BD6: =COUNTIF('One time execution_Milestone'!CP4:CP64,"3. Missing baseline") -> 0 | BE6: =COUNTIF([3]P0!CVW3:CVW36,"3. Missing baseline") -> #VALUE! | BF6: =COUNTIF('[3]P1(Stopwatch)'!UH3:UH41,"3. Missing baseline")+COUNTIF([3]P1_P2_P3_Automation!CAO3:CAO17,"3. Missing baseline") -> #VALUE! | BG6: =COUNTIF('[3]P2(Stopwatch)'!SX3:SX30,"3. Missing baseline")+COUNTIF([3]P1_P2_P3_Automation!CAO18:CAO31,"3. Missing baseline") -> #VALUE! | BH6: =COUNTIF('[3]P3(Stopwatch)'!VO3:VO23,"3. Missing baseline")+COUNTIF([3]P1_P2_P3_Automation!CAO32:CAO32,"3. Missing baseline") -> #VALUE! | BI6: =COUNTIF([3]P0!CVX3:CVX36,"3. Missing baseline") -> #VALUE! | BJ6: =COUNTIF('[3]P1(Stopwatch)'!UL3:UL41,"3. Missing baseline")+COUNTIF([3]P1_P2_P3_Automation!CAS3:CAS17,"3. Missing baseline") -> #VALUE! | BK6: =COUNTIF('[3]P2(Stopwatch)'!TB3:TB30,"3. Missing baseline")+COUNTIF([3]P1_P2_P3_Automation!CAS18:CAS31,"3. Missing baseline") -> #VALUE! | BL6: =COUNTIF('[3]P3(Stopwatch)'!VS3:VS23,"3. Missing baseline")+COUNTIF([3]P1_P2_P3_Automation!CAS32:CAS32,"3. Missing baseline") -> #VALUE! | BM6: =COUNTIF([3]P0!CVY3:CVY36,"3. Missing baseline")+COUNTIF('[3]P0 Pisco & Barolo'!CP5:CP24,"3. Missing baseline")+COUNTIF('[3]Canvas and Structured '!BV4:BV11,"3. Missing baseline") -> #VALUE! | BN6: =COUNTIF('[3]P1(Stopwatch)'!UP3:UP41,"3. Missing baseline")+COUNTIF([3]P1_P2_P3_Automation!CAW3:CAW17,"3. Missing baseline") -> #VALUE! | BO6: =COUNTIF('[3]P2(Stopwatch)'!TF3:TF30,"3. Missing baseline")+COUNTIF([3]P1_P2_P3_Automation!CAW18:CAW31,"3. Missing baseline") -> #VALUE! | BP6: =COUNTIF('[3]P3(Stopwatch)'!VW3:VW23,"3. Missing baseline")+COUNTIF([3]P1_P2_P3_Automation!CAW32:CAW32,"3. Missing baseline") -> #VALUE! | BQ6: =COUNTIF([3]P0_Seabreeze!BU3:BU65,"3. Missing baseline ") -> #VALUE! | BR6: =COUNTIF('[3]P1(Stopwatch)'!UT3:UT41,"3. Missing baseline")+COUNTIF([3]P1_P2_P3_Automation!CBA3:CBA17,"3. Missing baseline") -> #VALUE! | BS6: =COUNTIF('[3]P2(Stopwatch)'!TJ3:TJ30,"3. Missing baseline")+COUNTIF([3]P1_P2_P3_Automation!CBA18:CBA31,"3. Missing baseline") -> #VALUE! | BT6: =COUNTIF('[3]P3(Stopwatch)'!WA3:WA23,"3. Missing baseline")+COUNTIF([3]P1_P2_P3_Automation!CBA32:CBA32,"3. Missing baseline") -> #VALUE!
A7: 4.Blocker/Not Executed | B7: =COUNTIF('P0_All Devices'!DRL3:DRL36,"4.Blocker/Not Executed") -> 0 | C7: =COUNTIF('P1(Stopwatch)'!ACE3:ACE7,"4.Blocker/Not Executed")+COUNTIF(P1_P2_P3_Automation!CAJ3:CAJ15,"4.Blocker/Not Executed") -> 3 | D7: =COUNTIF('P2(Stopwatch)'!AAN3:AAN18,"4.Blocker/Not Executed")+COUNTIF(P1_P2_P3_Automation!CAJ18:CAJ31,"4.Blocker/Not Executed") -> 1 | E7: =COUNTIF('P3(Stopwatch)'!ABK3:ABK12,"4.Blocker/Not Executed")+COUNTIF(P1_P2_P3_Automation!CAJ32:CAJ32,"4.Blocker/Not Executed") -> 1 | F7: =COUNTIF('One time execution_Milestone'!BT4:BT64,"4.Blocker/Not Executed") -> 0 | G7: =COUNTIF('P0_All Devices'!DRM3:DRM36,"4.Blocker/Not Executed") -> 0 | H7: =COUNTIF('P1(Stopwatch)'!ACF3:ACF7,"4.Blocker/Not Executed")+COUNTIF(P1_P2_P3_Automation!CAK3:CAK11,"4.Blocker/Not Executed") -> 0 | I7: =COUNTIF('P2(Stopwatch)'!AAO3:AAO14,"4.Blocker/Not Executed")+COUNTIF(P1_P2_P3_Automation!CAK18:CAK31,"4.Blocker/Not Executed") -> 9 | J7: =COUNTIF('P3(Stopwatch)'!ABL3:ABL3,"4.Blocker/Not Executed")+COUNTIF(P1_P2_P3_Automation!CAK32:CAK32,"4.Blocker/Not Executed") -> 0 | K7: =COUNTIF('One time execution_Milestone'!BW4:BW64,"4.Blocker/Not Executed") -> 0 | L7: =COUNTIF('P0_All Devices'!DRN3:DRN36,"4.Blocker/Not Executed") -> 0 | M7: =COUNTIF('P1(Stopwatch)'!ACG3:ACG7,"4.Blocker/Not Executed")+COUNTIF(P1_P2_P3_Automation!CAL3:CAL15,"4.Blocker/Not Executed") -> 3 | N7: =COUNTIF('P2(Stopwatch)'!AAP3:AAP18,"4.Blocker/Not Executed")+COUNTIF(P1_P2_P3_Automation!CAL18:CAL31,"4.Blocker/Not Executed") -> 8 | O7: =COUNTIF('P3(Stopwatch)'!ABM3:ABM12,"4.Blocker/Not Executed")+COUNTIF(P1_P2_P3_Automation!CAL32:CAL32,"4.Blocker/Not Executed") -> 5 | P7: =COUNTIF('One time execution_Milestone'!BV4:BV64,"4.Blocker/Not Executed") -> 0 | Q7: =COUNTIF('P0_All Devices'!DRO3:DRO36,"4.Blocker/Not Executed") -> 0 | R7: =COUNTIF('P1(Stopwatch)'!ACH3:ACH7,"4.Blocker/Not Executed")+COUNTIF(P1_P2_P3_Automation!CAM3:CAM15,"4.Blocker/Not Executed") -> 3 | S7: =COUNTIF('P2(Stopwatch)'!AAQ3:AAQ18,"4.Blocker/Not Executed")+COUNTIF(P1_P2_P3_Automation!CAM18:CAM31,"4.Blocker/Not Executed") -> 1 | T7: =COUNTIF('P3(Stopwatch)'!ABN3:ABN12,"4.Blocker/Not Executed")+COUNTIF(P1_P2_P3_Automation!CAM32:CAM32,"4.Blocker/Not Executed") -> 1 | U7: =COUNTIF('One time execution_Milestone'!BW4:BW64,"4.Blocker/Not Executed") -> 0 | V7: =COUNTIF('P0_All Devices'!DRP3:DRP36,"4.Blocker/Not Executed") -> 0 | W7: =COUNTIF('P1(Stopwatch)'!ACI3:ACI7,"4.Blocker/Not Executed")+COUNTIF(P1_P2_P3_Automation!CAN3:CAN15,"4.Blocker/Not Executed") -> 3 | X7: =COUNTIF('P2(Stopwatch)'!AAR3:AAR18,"4.Blocker/Not Executed")+COUNTIF(P1_P2_P3_Automation!CAN18:CAN31,"4.Blocker/Not Executed") -> 1 | Y7: =COUNTIF('P3(Stopwatch)'!ABO3:ABO12,"4.Blocker/Not Executed")+COUNTIF(P1_P2_P3_Automation!CAN32:CAN32,"4.Blocker/Not Executed") -> 0 | Z7: =COUNTIF('One time execution_Milestone'!BX4:BX64,"4.Blocker/Not Executed") -> 0 | AA7: =COUNTIF('P0_All Devices'!DRQ3:DRQ36,"4.Blocker/Not Executed") -> 0 | AB7: =COUNTIF('P1(Stopwatch)'!ACJ3:ACJ7,"4.Blocker/Not Executed")+COUNTIF(P1_P2_P3_Automation!CAO3:CAO15,"4.Blocker/Not Executed") -> 0 | AC7: =COUNTIF('P2(Stopwatch)'!AAS3:AAS18,"4.Blocker/Not Executed")+COUNTIF(P1_P2_P3_Automation!CAO18:CAO31,"4.Blocker/Not Executed") -> 3 | AD7: =COUNTIF('P3(Stopwatch)'!ABP3:ABP12,"4.Blocker/Not Executed")+COUNTIF(P1_P2_P3_Automation!CAO32:CAO32,"4.Blocker/Not Executed") -> 1 | AE7: =COUNTIF('One time execution_Milestone'!BY4:BY64,"4.Blocker/Not Executed") -> 0 | AF7: =COUNTIF('P0_All Devices'!DRR3:DRR36,"4.Blocker/Not Executed") -> 0 | AG7: =COUNTIF('P1(Stopwatch)'!ACK3:ACK7,"4.Blocker/Not Executed")+COUNTIF(P1_P2_P3_Automation!CAP3:CAP15,"4.Blocker/Not Executed") -> 0 | AH7: =COUNTIF('P2(Stopwatch)'!AAT3:AAT18,"4.Blocker/Not Executed")+COUNTIF(P1_P2_P3_Automation!CAP18:CAP31,"4.Blocker/Not Executed") -> 0 | AI7: =COUNTIF('P3(Stopwatch)'!ABQ3:ABQ12,"4.Blocker/Not Executed")+COUNTIF(P1_P2_P3_Automation!CAP32:CAP32,"4.Blocker/Not Executed") -> 1 | AJ7: =COUNTIF('One time execution_Milestone'!BZ4:BZ64,"4.Blocker/Not Executed") -> 6 | AK7: =COUNTIF('P0_All Devices'!DRS3:DRS36,"4.Blocker/Not Executed") -> 0 | AL7: =COUNTIF('P1(Stopwatch)'!ACL3:ACL7,"4.Blocker/Not Executed")+COUNTIF(P1_P2_P3_Automation!CAQ3:CAQ15,"4.Blocker/Not Executed") -> 0 | AM7: =COUNTIF('P2(Stopwatch)'!AAU3:AAU18,"4.Blocker/Not Executed")+COUNTIF(P1_P2_P3_Automation!CAY18:CAY31,"4.Blocker/Not Executed") -> 3 | AN7: =COUNTIF('P3(Stopwatch)'!ABR3:ABR12,"4.Blocker/Not Executed")+COUNTIF(P1_P2_P3_Automation!CAY32:CAY32,"4.Blocker/Not Executed") -> 0 | AO7: =COUNTIF('One time execution_Milestone'!CA4:CA64,"4.Blocker/Not Executed") -> 0 | AP7: =COUNTIF('P0_All Devices'!DRT3:DRT36,"4.Blocker/Not Executed") -> 0 | AQ7: =COUNTIF('P1(Stopwatch)'!ACN3:ACN7,"4.Blocker/Not Executed")+COUNTIF(P1_P2_P3_Automation!CAR3:CAR15,"4.Blocker/Not Executed") -> 0 | AR7: =COUNTIF('P2(Stopwatch)'!AAV3:AAV18,"4.Blocker/Not Executed")+COUNTIF(P1_P2_P3_Automation!CAR18:CAR31,"4.Blocker/Not Executed") -> 4 | AS7: =COUNTIF('P3(Stopwatch)'!ABS3:ABS12,"4.Blocker/Not Executed")+COUNTIF(P1_P2_P3_Automation!CAR32:CAR32,"4.Blocker/Not Executed") -> 1 | AT7: =COUNTIF('One time execution_Milestone'!CF4:CF64,"4.Blocker/Not Executed") -> 0 | AU7: =COUNTIF('P0_All Devices'!DRU3:DRU36,"4.Blocker/Not Executed") -> 0 | AV7: =COUNTIF('P1(Stopwatch)'!ACO3:ACO8,"4.Blocker/Not Executed")+COUNTIF(P1_P2_P3_Automation!CAW3:CAW15,"4.Blocker/Not Executed") -> 0 | AW7: =COUNTIF('P2(Stopwatch)'!AAW3:AAW18,"4.Blocker/Not Executed")+COUNTIF(P1_P2_P3_Automation!CAS18:CAS31,"4.Blocker/Not Executed") -> 4 | AX7: =COUNTIF('P3(Stopwatch)'!ABT3:ABT12,"4.Blocker/Not Executed")+COUNTIF(P1_P2_P3_Automation!CAS32:CAS32,"4.Blocker/Not Executed") -> 1 | AY7: =COUNTIF('One time execution_Milestone'!CK4:CK64,"4.Blocker/Not Executed") -> 0 | AZ7: =COUNTIF('P0_All Devices'!DRV3:DRV36,"4.Blocker/Not Executed") -> 0 | BA7: =COUNTIF('P1(Stopwatch)'!ACP3:ACP7,"4.Blocker/Not Executed")+COUNTIF(P1_P2_P3_Automation!CAT3:CAT17,"4.Blocker/Not Executed") -> 2 | BB7: =COUNTIF('P2(Stopwatch)'!AAX3:AAX18,"4.Blocker/Not Executed")+COUNTIF(P1_P2_P3_Automation!CAT18:CAT31,"4.Blocker/Not Executed") -> 8 | BC7: =COUNTIF('P3(Stopwatch)'!ABU3:ABU12,"4.Blocker/Not Executed")+COUNTIF(P1_P2_P3_Automation!CAT32:CAT32,"4.Blocker/Not Executed") -> 0 | BD7: =COUNTIF('One time execution_Milestone'!CP4:CP64,"4.Blocker/Not Executed") -> 0 | BE7: =COUNTIF([3]P0!CVW3:CVW36,"4.Blocker/Not Executed") -> #VALUE! | BF7: =COUNTIF('[3]P1(Stopwatch)'!UH3:UH41,"4.Blocker/Not Executed")+COUNTIF([3]P1_P2_P3_Automation!CAO3:CAO17,"4.Blocker/Not Executed") -> #VALUE! | BG7: =COUNTIF('[3]P2(Stopwatch)'!SX3:SX30,"4.Blocker/Not Executed")+COUNTIF([3]P1_P2_P3_Automation!CAO18:CAO31,"4.Blocker/Not Executed") -> #VALUE! | BH7: =COUNTIF('[3]P3(Stopwatch)'!VO3:VO23,"4.Blocker/Not Executed")+COUNTIF([3]P1_P2_P3_Automation!CAO32:CAO32,"4.Blocker/Not Executed") -> #VALUE! | BI7: =COUNTIF([3]P0!CVX3:CVX36,"4.Blocker/Not Executed") -> #VALUE! | BJ7: =COUNTIF('[3]P1(Stopwatch)'!UL3:UL41,"4.Blocker/Not Executed")+COUNTIF([3]P1_P2_P3_Automation!CAS3:CAS17,"4.Blocker/Not Executed") -> #VALUE! | BK7: =COUNTIF('[3]P2(Stopwatch)'!TB3:TB30,"4.Blocker/Not Executed")+COUNTIF([3]P1_P2_P3_Automation!CAS18:CAS31,"4.Blocker/Not Executed") -> #VALUE! | BL7: =COUNTIF('[3]P3(Stopwatch)'!VS3:VS23,"4.Blocker/Not Executed")+COUNTIF([3]P1_P2_P3_Automation!CAS32:CAS32,"4.Blocker/Not Executed") -> #VALUE! | BM7: =COUNTIF([3]P0!CVY3:CVY36,"4.Blocker/Not Executed")+COUNTIF('[3]P0 Pisco & Barolo'!CP5:CP24,"4.Blocker/Not Executed")+COUNTIF('[3]Canvas and Structured '!BV4:BV11,"4.Blocker/Not Executed") -> #VALUE! | BN7: =COUNTIF('[3]P1(Stopwatch)'!UP3:UP41,"4.Blocker/Not Executed")+COUNTIF([3]P1_P2_P3_Automation!CAW3:CAW17,"4.Blocker/Not Executed") -> #VALUE! | BO7: =COUNTIF('[3]P2(Stopwatch)'!TF3:TF30,"4.Blocker/Not Executed")+COUNTIF([3]P1_P2_P3_Automation!CAW18:CAW31,"4.Blocker/Not Executed") -> #VALUE! | BP7: =COUNTIF('[3]P3(Stopwatch)'!VW3:VW23,"4.Blocker/Not Executed")+COUNTIF([3]P1_P2_P3_Automation!CAW32:CAW32,"4.Blocker/Not Executed") -> #VALUE! | BQ7: =COUNTIF([3]P0_Seabreeze!BU3:BU65,"4.Blocker/Not Executed") -> #VALUE! | BR7: =COUNTIF('[3]P1(Stopwatch)'!UT3:UT41,"4.Blocker/Not Executed")+COUNTIF([3]P1_P2_P3_Automation!CBA3:CBA17,"4.Blocker/Not Executed") -> #VALUE! | BS7: =COUNTIF('[3]P2(Stopwatch)'!TJ3:TJ30,"4.Blocker/Not Executed")+COUNTIF([3]P1_P2_P3_Automation!CBA18:CBA31,"4.Blocker/Not Executed") -> #VALUE! | BT7: =COUNTIF('[3]P3(Stopwatch)'!WA3:WA23,"4.Blocker/Not Executed")+COUNTIF([3]P1_P2_P3_Automation!CBA32:CBA32,"4.Blocker/Not Executed") -> #VALUE!
A8: Total | B8: =SUM(B4:B7) -> 34 | C8: =SUM(C4:C7) -> 18 | D8: =SUM(D4:D7) -> 30 | E8: =SUM(E4:E7) -> 11 | F8: =SUM(F4:F7) -> 55 | G8: =SUM(G4:G7) -> 34 | H8: =SUM(H4:H7) -> 14 | I8: =SUM(I4:I7) -> 26 | ... BT8: =SUM(BT4:BT7) -> #VALUE!

Sheet P0_All Devices
T1: Eanab | II1: Icewine | ML1: Muscat | US1: Whisky | ADC1: Cognac | ALW1: Moonshine | AYT1: Jaeger | BLC1: Stinger | BYP1: Malbec | CIO1: Cava | CQE1: Barolo | DCS1: Rossini | DGM1: Rossini | DLY1: Sangria | DNP1: Pisco
